Workbook

Sheet Cleaned_dataset
A1: Product ID | B1: SKU | C1: Product | D1: Category | E1: Brand | F1: Supplier | G1: Unit Cost (£) | H1: Selling Price (£) | I1: Stock Quantity | J1: Reorder Level | K1: Warehouse Location | L1: Last Restocked | M1: Stock Value | N1: Reorder Flag
A2: PRD00001 | B2: EC-ELE-0001 | C2: PixelWorks Travel Webcam | D2: Electronics | E2: Pixelworks | F2: Dovetail Trading Co. | G2: 81.1 | H2: 188.36 | I2: 215 | J2: 40 | K2: LON-A1 | L2: 46195 | M2: =IF(I2="","Unavailable",G2*I2) -> 17436.5 | N2: =IF(I2="","Unavailable",IF(I2<=J2,"Reorder","Sufficient Stock")) -> Sufficient Stock
A3: PRD00002 | B3: EC-ELE-0002 | C3: Everyday Co. Pro Phone Charger | D3: Electronics | E3: Everyday Co. | F3: Everwell Supply | G3: 69.66 | H3: 146.54 | I3: 160 | J3: 15 | K3: MAN-A1 | M3: =IF(I3="","Unavailable",G3*I3) -> 11145.6 | N3: =IF(I3="","Unavailable",IF(I3<=J3,"Reorder","Sufficient Stock")) -> Sufficient Stock
A4: PRD00003 | B4: EC-HOM-0003 | C4: Kindred Travel LED Strip Lights | D4: Home & Office | E4: Kindred | F4: Juniper Merchants | G4: 9.62 | H4: 18.68 | I4: 147 | J4: 40 | K4: MAN-A1 | L4: 45580 | M4: =IF(I4="","Unavailable",G4*I4) -> 1414.14 | N4: =IF(I4="","Unavailable",IF(I4<=J4,"Reorder","Sufficient Stock")) -> Sufficient Stock
A5: PRD00004 | B5: EC-KIT-0004 | C5: PixelWorks Essential Food Storage Set - Charcoal | D5: Kitchen | E5: Pixelworks | F5: Greenway Goods | G5: 75.97 | H5: 148.89 | I5: 59 | J5: 30 | K5: GLA-A2 | L5: 46297 | M5: =IF(I5="","Unavailable",G5*I5) -> 4482.23 | N5: =IF(I5="","Unavailable",IF(I5<=J5,"Reorder","Sufficient Stock")) -> Sufficient Stock
A6: PRD00005 | B6: EC-ACC-0005 | C6: Kite & Key Essential Screen Protector | D6: Accessories | E6: Kite & Key | F6: Juniper Merchants | G6: 4.3 | H6: 6.87 | I6: 66 | J6: 5 | K6: BHM-C3 | L6: 45502 | M6: =IF(I6="","Unavailable",G6*I6) -> 283.8 | N6: =IF(I6="","Unavailable",IF(I6<=J6,"Reorder","Sufficient Stock")) -> Sufficient Stock
A7: PRD00006 | B7: EC-HOM-0006 | C7: Morrow Everyday Desk Lamp | D7: Home & Office | E7: Morrow | F7: Ivory Peak Logistics | G7: 40.02 | H7: 74.69 | I7: 128 | J7: 30 | K7: LDS-B1 | L7: 45922 | M7: =IF(I7="","Unavailable",G7*I7) -> 5122.56 | N7: =IF(I7="","Unavailable",IF(I7<=J7,"Reorder","Sufficient Stock")) -> Sufficient Stock
A8: PRD00007 | B8: EC-BEA-0007 | C8: Harbour & Hill Deluxe Hand Cream | D8: Beauty | E8: Harbour & Hill | F8: Dovetail Trading Co. | G8: 24.48 | H8: 33.94 | J8: 40 | K8: MAN-A1 | L8: 46029 | M8: =IF(I8="","Unavailable",G8*I8) -> Unavailable | N8: =IF(I8="","Unavailable",IF(I8<=J8,"Reorder","Sufficient Stock")) -> Unavailable
A9: PRD00008 | B9: EC-BEA-0008 | C9: Morrow Travel Shampoo | D9: Beauty | E9: Morrow | F9: Bluegate Distribution | G9: 48.39 | H9: 113.62 | I9: 148 | J9: 25 | K9: BHM-C3 | L9: 46229 | M9: =IF(I9="","Unavailable",G9*I9) -> 7161.72 | N9: =IF(I9="","Unavailable",IF(I9<=J9,"Reorder","Sufficient Stock")) -> Sufficient Stock
A10: PRD00009 | B10: EC-PET-0009 | C10: Oak & Ember Essential Dog Lead | D10: Pet Supplies | E10: Oak & Ember | F10: Unknown | G10: 71.95 | H10: 135.05 | I10: 32 | J10: 20 | K10: LON-A1 | L10: 46312 | M10: =IF(I10="","Unavailable",G10*I10) -> 2302.4 | N10: =IF(I10="","Unavailable",IF(I10<=J10,"Reorder","Sufficient Stock")) -> Sufficient Stock
A11: PRD00010 | B11: EC-ACC-0010 | C11: Urban Field Essential Screen Protector - Black | D11: Accessories | E11: Urban Field | F11: Bluegate Distribution | G11: 39.56 | H11: 77.19 | I11: 42 | J11: 15 | K11: GLA-A2 | L11: 45799 | M11: =IF(I11="","Unavailable",G11*I11) -> 1661.52 | N11: =IF(I11="","Unavailable",IF(I11<=J11,"Reorder","Sufficient Stock")) -> Sufficient Stock
A12: PRD00011 | B12: EC-GAR-0011 | C12: Oak & Ember Eco Garden Gloves - Rose | D12: Garden | E12: Oak & Ember | F12: Harbour Stockists | G12: 28.15 | H12: 56.06 | I12: 251 | J12: 12 | K12: GLA-A2 | M12: =IF(I12="","Unavailable",G12*I12) -> 7065.65 | N12: =IF(I12="","Unavailable",IF(I12<=J12,"Reorder","Sufficient Stock")) -> Sufficient Stock
A13: PRD00012 | B13: EC-TRA-0012 | C13: Kindred Travel Packing Cubes - Sage | D13: Travel | E13: Kindred | F13: Crownline Imports | G13: 57.56 | H13: 136.91 | I13: 156 | J13: 30 | K13: GLA-A2 | L13: 46091 | M13: =IF(I13="","Unavailable",G13*I13) -> 8979.36 | N13: =IF(I13="","Unavailable",IF(I13<=J13,"Reorder","Sufficient Stock")) -> Sufficient Stock
A14: PRD00013 | B14: EC-HOM-0013 | C14: Northstar Compact LED Strip Lights | D14: Home & Office | E14: Northstar | F14: Ivory Peak Logistics | G14: 6.45 | H14: 11.17 | I14: 180 | J14: 5 | K14: BHM-C3 | L14: 45344 | M14: =IF(I14="","Unavailable",G14*I14) -> 1161 | N14: =IF(I14="","Unavailable",IF(I14<=J14,"Reorder","Sufficient Stock")) -> Sufficient Stock
A15: PRD00014 | B15: EC-FIT-0014 | C15: Morrow Mini Yoga Mat | D15: Fitness | E15: Morrow | F15: Greenway Goods | G15: 40.83 | H15: 82.9 | I15: 87 | J15: 12 | K15: GLA-A2 | L15: 45715 | M15: =IF(I15="","Unavailable",G15*I15) -> 3552.21 | N15: =IF(I15="","Unavailable",IF(I15<=J15,"Reorder","Sufficient Stock")) -> Sufficient Stock
A16: PRD00015 | B16: EC-BEA-0015 | C16: Kite & Key Everyday Facial Cleanser | D16: Beauty | E16: Kite & Key | F16: Harbour Stockists | G16: 5.03 | H16: 10.37 | I16: 88 | J16: 5 | K16: LDS-B1 | L16: 45390 | M16: =IF(I16="","Unavailable",G16*I16) -> 442.64 | N16: =IF(I16="","Unavailable",IF(I16<=J16,"Reorder","Sufficient Stock")) -> Sufficient Stock
A17: PRD00016 | B17: EC-BEA-0016 | C17: Kindred Eco Hand Cream - Black | D17: Beauty | E17: Kindred | F17: Greenway Goods | G17: 46.08 | H17: 102.02 | I17: 70 | J17: 12 | K17: MAN-A1 | L17: 45672 | M17: =IF(I17="","Unavailable",G17*I17) -> 3225.6 | N17: =IF(I17="","Unavailable",IF(I17<=J17,"Reorder","Sufficient Stock")) -> Sufficient Stock
A18: PRD00017 | B18: EC-GAR-0017 | C18: Harbour & Hill Compact Garden Gloves | D18: Garden | E18: Harbour & Hill | F18: Harbour Stockists | G18: 30.69 | H18: 50.33 | I18: 254 | J18: 30 | K18: LON-B2 | L18: 45881 | M18: =IF(I18="","Unavailable",G18*I18) -> 7795.26 | N18: =IF(I18="","Unavailable",IF(I18<=J18,"Reorder","Sufficient Stock")) -> Sufficient Stock
A19: PRD00018 | B19: EC-PET-0018 | C19: Morrow Essential Cat Toy | D19: Pet Supplies | E19: Morrow | F19: Aster Wholesale Ltd | G19: 45.65 | H19: 75.38 | I19: 48 | J19: 15 | K19: LON-A1 | L19: 45765 | M19: =IF(I19="","Unavailable",G19*I19) -> 2191.2 | N19: =IF(I19="","Unavailable",IF(I19<=J19,"Reorder","Sufficient Stock")) -> Sufficient Stock
A20: PRD00019 | B20: EC-KIT-0019 | C20: Harbour & Hill Travel Coffee Grinder | D20: Kitchen | E20: Harbour & Hill | F20: Ivory Peak Logistics | G20: 31.34 | H20: 47.71 | I20: 110 | J20: 10 | K20: GLA-A2 | L20: 45866 | M20: =IF(I20="","Unavailable",G20*I20) -> 3447.4 | N20: =IF(I20="","Unavailable",IF(I20<=J20,"Reorder","Sufficient Stock")) -> Sufficient Stock
A21: PRD00020 | B21: EC-HOM-0020 | C21: Kite & Key Pro Water Bottle | D21: Home & Office | E21: Kite & Key | F21: Crownline Imports | G21: 48.21 | H21: 70.46 | I21: 135 | J21: 10 | K21: LON-A1 | L21: 46185 | M21: =IF(I21="","Unavailable",G21*I21) -> 6508.35 | N21: =IF(I21="","Unavailable",IF(I21<=J21,"Reorder","Sufficient Stock")) -> Sufficient Stock
A22: PRD00021 | B22: EC-ELE-0021 | C22: PixelWorks Plus Laptop Stand | D22: Electronics | E22: Pixelworks | F22: Crownline Imports | G22: 11 | H22: 18.64 | I22: 32 | J22: 20 | K22: MAN-A1 | L22: 45936 | M22: =IF(I22="","Unavailable",G22*I22) -> 352 | N22: =IF(I22="","Unavailable",IF(I22<=J22,"Reorder","Sufficient Stock")) -> Sufficient Stock
A23: PRD00022 | B23: EC-ELE-0022 | C23: Northstar Deluxe Mechanical Keyboard | D23: Electronics | E23: Northstar | F23: Bluegate Distribution | G23: 3.48 | H23: 5.07 | I23: 11 | J23: 20 | K23: LDS-B1 | L23: 45543 | M23: =IF(I23="","Unavailable",G23*I23) -> 38.28 | N23: =IF(I23="","Unavailable",IF(I23<=J23,"Reorder","Sufficient Stock")) -> Reorder
A24: PRD00023 | B24: EC-BOO-0023 | C24: PixelWorks Mini Cookbook | D24: Books | E24: Pixelworks | F24: Juniper Merchants | G24: 56.41 | H24: 114.32 | I24: 206 | J24: 25 | K24: BHM-C3 | L24: 45733 | M24: =IF(I24="","Unavailable",G24*I24) -> 11620.46 | N24: =IF(I24="","Unavailable",IF(I24<=J24,"Reorder","Sufficient Stock")) -> Sufficient Stock
... A55: PRD00054 | B55: EC-STA-0054 | C55: Nova Supply Premium Ballpoint Pens | D55: Stationery | E55: Nova Supply | F55: Ivory Peak Logistics | G55: 42.75 | H55: 83.39 | I55: 14 | J55: 20 | K55: MAN-A1 | L55: 45744 | M55: =IF(I55="","Unavailable",G55*I55) -> 598.5 | N55: =IF(I55="","Unavailable",IF(I55<=J55,"Reorder","Sufficient Stock")) -> Reorder
A56: PRD00055 | B56: EC-ELE-0055 | C56: Morrow Eco Phone Charger - Charcoal | D56: Electronics | E56: Morrow | F56: Aster Wholesale Ltd | G56: 29.07 | H56: 62.1 | I56: 20 | J56: 40 | K56: LON-A1 | M56: =IF(I56="","Unavailable",G56*I56) -> 581.4 | N56: =IF(I56="","Unavailable",IF(I56<=J56,"Reorder","Sufficient Stock")) -> Reorder
A57: PRD00056 | B57: EC-HOM-0056 | C57: Kindred Plus Desk Organiser | D57: Home & Office | E57: Kindred | F57: Dovetail Trading Co. | G57: 4.53 | H57: 8.62 | I57: 46 | J57: 30 | K57: LON-B2 | L57: 46179 | M57: =IF(I57="","Unavailable",G57*I57) -> 208.38 | N57: =IF(I57="","Unavailable",IF(I57<=J57,"Reorder","Sufficient Stock")) -> Sufficient Stock
A58: PRD00057 | B58: EC-APP-0057 | C58: Nova Supply Essential Cotton T-Shirt | D58: Apparel | E58: Nova Supply | F58: Dovetail Trading Co. | G58: 46.57 | H58: 107.46 | I58: 216 | J58: 40 | K58: MAN-A1 | L58: 46035 | M58: =IF(I58="","Unavailable",G58*I58) -> 10059.12 | N58: =IF(I58="","Unavailable",IF(I58<=J58,"Reorder","Sufficient Stock")) -> Sufficient Stock
A59: PRD00058 | B59: EC-ACC-0058 | C59: Cedar Lane Studio Sunglasses - Blue | D59: Accessories | E59: Cedar Lane | F59: Juniper Merchants | G59: 76.47 | H59: 165.4 | I59: 59 | J59: 10 | K59: LDS-B1 | L59: 46016 | M59: =IF(I59="","Unavailable",G59*I59) -> 4511.73 | N59: =IF(I59="","Unavailable",IF(I59<=J59,"Reorder","Sufficient Stock")) -> Sufficient Stock
A60: PRD00059 | B60: EC-ELE-0059 | C60: Urban Field Everyday Webcam - Charcoal | D60: Electronics | E60: Urban Field | F60: Everwell Supply | G60: 80.69 | H60: 196.18 | I60: 15 | J60: 12 | K60: LDS-B1 | L60: 45842 | M60: =IF(I60="","Unavailable",G60*I60) -> 1210.35 | N60: =IF(I60="","Unavailable",IF(I60<=J60,"Reorder","Sufficient Stock")) -> Sufficient Stock
A61: PRD00060 | B61: EC-ACC-0060 | C61: Northstar Essential Phone Case | D61: Accessories | E61: Northstar | F61: Ivory Peak Logistics | G61: 24.81 | H61: 43.16 | I61: 70 | J61: 10 | K61: LON-B2 | L61: 45586 | M61: =IF(I61="","Unavailable",G61*I61) -> 1736.7 | N61: =IF(I61="","Unavailable",IF(I61<=J61,"Reorder","Sufficient Stock")) -> Sufficient Stock
A62: PRD00061 | B62: EC-BEA-0061 | C62: Harbour & Hill Studio Facial Cleanser - Graphite | D62: Beauty | E62: Harbour & Hill | F62: Harbour Stockists | G62: 60.01 | H62: 117.99 | I62: 130 | J62: 10 | K62: MAN-A1 | L62: 46236 | M62: =IF(I62="","Unavailable",G62*I62) -> 7801.3 | N62: =IF(I62="","Unavailable",IF(I62<=J62,"Reorder","Sufficient Stock")) -> Sufficient Stock
A63: PRD00062 | B63: EC-PET-0062 | C63: Cedar Lane Compact Cat Toy | D63: Pet Supplies | E63: Cedar Lane | F63: Juniper Merchants | G63: 8.87 | H63: 12.38 | I63: 231 | J63: 10 | K63: BHM-C3 | L63: 46083 | M63: =IF(I63="","Unavailable",G63*I63) -> 2048.97 | N63: =IF(I63="","Unavailable",IF(I63<=J63,"Reorder","Sufficient Stock")) -> Sufficient Stock
A64: PRD00063 | B64: EC-BEA-0063 | C64: Cedar Lane Classic Hand Cream | D64: Beauty | E64: Cedar Lane | F64: Aster Wholesale Ltd | G64: 13.32 | H64: 19.52 | I64: 47 | J64: 12 | K64: LON-A1 | L64: 45814 | M64: =IF(I64="","Unavailable",G64*I64) -> 626.04 | N64: =IF(I64="","Unavailable",IF(I64<=J64,"Reorder","Sufficient Stock")) -> Sufficient Stock
A65: PRD00064 | B65: EC-ELE-0064 | C65: Kite & Key Travel Mechanical Keyboard | D65: Electronics | E65: Kite & Key | F65: Dovetail Trading Co. | G65: 73.12 | H65: 125.65 | I65: 78 | J65: 20 | K65: MAN-A1 | L65: 46256 | M65: =IF(I65="","Unavailable",G65*I65) -> 5703.36 | N65: =IF(I65="","Unavailable",IF(I65<=J65,"Reorder","Sufficient Stock")) -> Sufficient Stock
A66: PRD00065 | B66: EC-BEA-0065 | C66: Kindred Everyday Facial Cleanser - Charcoal | D66: Beauty | E66: Kindred | F66: Juniper Merchants | G66: 73.51 | H66: 124.52 | I66: 21 | J66: 40 | K66: LON-B2 | L66: 45802 | M66: =IF(I66="","Unavailable",G66*I66) -> 1543.71 | N66: =IF(I66="","Unavailable",IF(I66<=J66,"Reorder","Sufficient Stock")) -> Reorder
A67: PRD00066 | B67: EC-HOM-0066 | C67: Everyday Co. Studio Ergonomic Chair | D67: Home & Office | E67: Everyday Co. | F67: Ivory Peak Logistics | G67: 42.18 | H67: 57.7 | I67: 111 | J67: 30 | K67: BHM-C3 | L67: 45361 | M67: =IF(I67="","Unavailable",G67*I67) -> 4681.98 | N67: =IF(I67="","Unavailable",IF(I67<=J67,"Reorder","Sufficient Stock")) -> Sufficient Stock
A68: PRD00067 | B68: EC-HOM-0067 | C68: Brightline Travel Travel Mug | D68: Home & Office | E68: Brightline | F68: Ivory Peak Logistics | G68: 37.95 | H68: 81.93 | I68: 13 | J68: 25 | K68: LON-A1 | L68: 45632 | M68: =IF(I68="","Unavailable",G68*I68) -> 493.35 | N68: =IF(I68="","Unavailable",IF(I68<=J68,"Reorder","Sufficient Stock")) -> Reorder
... A90: PRD00089 | B90: EC-ELE-0089 | C90: PixelWorks Everyday Phone Charger | D90: Electronics | E90: Pixelworks | F90: Aster Wholesale Ltd | G90: 80.9 | H90: 190.72 | I90: 216 | J90: 12 | K90: LDS-B1 | L90: 45478 | M90: =IF(I90="","Unavailable",G90*I90) -> 17474.4 | N90: =IF(I90="","Unavailable",IF(I90<=J90,"Reorder","Sufficient Stock")) -> Sufficient Stock
A91: PRD00090 | B91: EC-ACC-0090 | C91: Everyday Co. Essential Backpack - Blue | D91: Accessories | E91: Everyday Co. | F91: Greenway Goods | G91: 41.58 | H91: 90.31 | J91: 30 | K91: LDS-B1 | L91: 45663 | M91: =IF(I91="","Unavailable",G91*I91) -> Unavailable | N91: =IF(I91="","Unavailable",IF(I91<=J91,"Reorder","Sufficient Stock")) -> Unavailable
...

Sheet Working_dataset
A1: product_id | B1: sku | C1: Cleaned sku | D1: product_name | E1: Cleaned product name | F1: category | G1: Cleaned category | H1: brand | I1: Cleaned brand | J1: supplier | K1: Cleaned supplier | L1: unit_cost_gbp | M1: selling_price_gbp | N1: cleaned selling price gbp | O1: stock_quantity | P1: reorder_level | Q1: warehouse_location | R1: cleaned warehouse location | S1: last_restocked
A2: PRD00001 | B2: EC-ELE-0001 | C2: =UPPER(TRIM(B2)) -> EC-ELE-0001 | D2: PixelWorks Travel Webcam | E2: =TRIM(D2) -> PixelWorks Travel Webcam | F2: Electronics | G2: =PROPER(TRIM(F2)) -> Electronics | H2: PixelWorks | I2: {=PROPER(IF(TRIM(H2)<>"",TRIM(H2),IFERROR(INDEX('Brand Reference'!$A$2:$A$13,MATCH(TRUE,ISNUMBER(SEARCH('Brand Reference'!$A$2:$A$13,E2)),0)),"Unknown")))} -> Pixelworks | J2: Dovetail Trading Co. | K2: =IF(J2="","Unknown",TRIM(PROPER(J2))) -> Dovetail Trading Co. | L2: 81.1 | M2: 188.36 | N2: =VALUE(SUBSTITUTE(M2," GBP","")) -> 188.36 | O2: 215 | P2: 40 | Q2: LON-A1 | R2: =UPPER(TRIM(Q2)) -> LON-A1 | S2: 46195
A3: PRD00002 | B3: EC-ELE-0002 | C3: =UPPER(TRIM(B3)) -> EC-ELE-0002 | D3: Everyday Co. Pro Phone Charger | E3: =TRIM(D3) -> Everyday Co. Pro Phone Charger | F3: Electronics | G3: =PROPER(TRIM(F3)) -> Electronics | H3: Everyday Co. | I3: {=PROPER(IF(TRIM(H3)<>"",TRIM(H3),IFERROR(INDEX('Brand Reference'!$A$2:$A$13,MATCH(TRUE,ISNUMBER(SEARCH('Brand Reference'!$A$2:$A$13,E3)),0)),"Unknown")))} -> Everyday Co. | J3: Everwell Supply | K3: =IF(J3="","Unknown",TRIM(PROPER(J3))) -> Everwell Supply | L3: 69.66 | M3: 146.54 GBP | N3: =VALUE(SUBSTITUTE(M3," GBP","")) -> 146.54 | O3: 160 | P3: 15 | Q3: MAN-A1 | R3: =UPPER(TRIM(Q3)) -> MAN-A1
A4: PRD00003 | B4: ec-hom-0003 | C4: =UPPER(TRIM(B4)) -> EC-HOM-0003 | D4: Kindred Travel LED Strip Lights | E4: =TRIM(D4) -> Kindred Travel LED Strip Lights | F4: Home & Office | G4: =PROPER(TRIM(F4)) -> Home & Office | H4: Kindred | I4: {=PROPER(IF(TRIM(H4)<>"",TRIM(H4),IFERROR(INDEX('Brand Reference'!$A$2:$A$13,MATCH(TRUE,ISNUMBER(SEARCH('Brand Reference'!$A$2:$A$13,E4)),0)),"Unknown")))} -> Kindred | J4: Juniper Merchants | K4: =IF(J4="","Unknown",TRIM(PROPER(J4))) -> Juniper Merchants | L4: 9.62 | M4: 18.68 | N4: =VALUE(SUBSTITUTE(M4," GBP","")) -> 18.68 | O4: 147 | P4: 40 | Q4: MAN-A1 | R4: =UPPER(TRIM(Q4)) -> MAN-A1 | S4: 45580
A5: PRD00004 | B5: EC-KIT-0004 | C5: =UPPER(TRIM(B5)) -> EC-KIT-0004 | D5: PixelWorks Essential Food Storage Set - Charcoal | E5: =TRIM(D5) -> PixelWorks Essential Food Storage Set - Charcoal | F5: Kitchen | G5: =PROPER(TRIM(F5)) -> Kitchen | H5: PixelWorks | I5: {=PROPER(IF(TRIM(H5)<>"",TRIM(H5),IFERROR(INDEX('Brand Reference'!$A$2:$A$13,MATCH(TRUE,ISNUMBER(SEARCH('Brand Reference'!$A$2:$A$13,E5)),0)),"Unknown")))} -> Pixelworks | J5: Greenway Goods | K5: =IF(J5="","Unknown",TRIM(PROPER(J5))) -> Greenway Goods | L5: 75.97 | M5: 148.89 | N5: =VALUE(SUBSTITUTE(M5," GBP","")) -> 148.89 | O5: 59 | P5: 30 | Q5: GLA-A2 | R5: =UPPER(TRIM(Q5)) -> GLA-A2 | S5: 46297
A6: PRD00005 | B6: EC-ACC-0005 | C6: =UPPER(TRIM(B6)) -> EC-ACC-0005 | D6: Kite & Key Essential Screen Protector | E6: =TRIM(D6) -> Kite & Key Essential Screen Protector | F6: Accessories | G6: =PROPER(TRIM(F6)) -> Accessories | H6: Kite & Key | I6: {=PROPER(IF(TRIM(H6)<>"",TRIM(H6),IFERROR(INDEX('Brand Reference'!$A$2:$A$13,MATCH(TRUE,ISNUMBER(SEARCH('Brand Reference'!$A$2:$A$13,E6)),0)),"Unknown")))} -> Kite & Key | J6: Juniper Merchants | K6: =IF(J6="","Unknown",TRIM(PROPER(J6))) -> Juniper Merchants | L6: 4.3 | M6: 6.87 | N6: =VALUE(SUBSTITUTE(M6," GBP","")) -> 6.87 | O6: 66 | P6: 5 | Q6: BHM-C3 | R6: =UPPER(TRIM(Q6)) -> BHM-C3 | S6: 45502
A7: PRD00006 | B7: EC-HOM-0006 | C7: =UPPER(TRIM(B7)) -> EC-HOM-0006 | D7: Morrow Everyday Desk Lamp | E7: =TRIM(D7) -> Morrow Everyday Desk Lamp | F7: Home & Office | G7: =PROPER(TRIM(F7)) -> Home & Office | H7: MORROW | I7: {=PROPER(IF(TRIM(H7)<>"",TRIM(H7),IFERROR(INDEX('Brand Reference'!$A$2:$A$13,MATCH(TRUE,ISNUMBER(SEARCH('Brand Reference'!$A$2:$A$13,E7)),0)),"Unknown")))} -> Morrow | J7: Ivory Peak Logistics | K7: =IF(J7="","Unknown",TRIM(PROPER(J7))) -> Ivory Peak Logistics | L7: 40.02 | M7: 74.69 | N7: =VALUE(SUBSTITUTE(M7," GBP","")) -> 74.69 | O7: 128 | P7: 30 | Q7: LDS-B1 | R7: =UPPER(TRIM(Q7)) -> LDS-B1 | S7: 45922
A8: PRD00007 | B8: EC-BEA-0007 | C8: =UPPER(TRIM(B8)) -> EC-BEA-0007 | D8: Harbour & Hill Deluxe Hand Cream | E8: =TRIM(D8) -> Harbour & Hill Deluxe Hand Cream | F8: Beauty | G8: =PROPER(TRIM(F8)) -> Beauty | H8: HARBOUR & HILL | I8: {=PROPER(IF(TRIM(H8)<>"",TRIM(H8),IFERROR(INDEX('Brand Reference'!$A$2:$A$13,MATCH(TRUE,ISNUMBER(SEARCH('Brand Reference'!$A$2:$A$13,E8)),0)),"Unknown")))} -> Harbour & Hill | J8: Dovetail Trading Co. | K8: =IF(J8="","Unknown",TRIM(PROPER(J8))) -> Dovetail Trading Co. | L8: 24.48 | M8: 33.94 | N8: =VALUE(SUBSTITUTE(M8," GBP","")) -> 33.94 | P8: 40 | Q8: MAN-A1 | R8: =UPPER(TRIM(Q8)) -> MAN-A1 | S8: 46029
A9: PRD00008 | B9: EC-BEA-0008 | C9: =UPPER(TRIM(B9)) -> EC-BEA-0008 | D9: Morrow Travel Shampoo | E9: =TRIM(D9) -> Morrow Travel Shampoo | F9: beauty | G9: =PROPER(TRIM(F9)) -> Beauty | H9: Morrow | I9: {=PROPER(IF(TRIM(H9)<>"",TRIM(H9),IFERROR(INDEX('Brand Reference'!$A$2:$A$13,MATCH(TRUE,ISNUMBER(SEARCH('Brand Reference'!$A$2:$A$13,E9)),0)),"Unknown")))} -> Morrow | J9: Bluegate Distribution | K9: =IF(J9="","Unknown",TRIM(PROPER(J9))) -> Bluegate Distribution | L9: 48.39 | M9: 113.62 | N9: =VALUE(SUBSTITUTE(M9," GBP","")) -> 113.62 | O9: 148 | P9: 25 | Q9: BHM-C3 | R9: =UPPER(TRIM(Q9)) -> BHM-C3 | S9: 46229
A10: PRD00009 | B10: EC-PET-0009 | C10: =UPPER(TRIM(B10)) -> EC-PET-0009 | D10: Oak & Ember Essential Dog Lead | E10: =TRIM(D10) -> Oak & Ember Essential Dog Lead | F10: Pet Supplies | G10: =PROPER(TRIM(F10)) -> Pet Supplies | H10: Oak & Ember | I10: {=PROPER(IF(TRIM(H10)<>"",TRIM(H10),IFERROR(INDEX('Brand Reference'!$A$2:$A$13,MATCH(TRUE,ISNUMBER(SEARCH('Brand Reference'!$A$2:$A$13,E10)),0)),"Unknown")))} -> Oak & Ember | K10: =IF(J10="","Unknown",TRIM(PROPER(J10))) -> Unknown | L10: 71.95 | M10: 135.05 | N10: =VALUE(SUBSTITUTE(M10," GBP","")) -> 135.05 | O10: 32 | P10: 20 | Q10: LON-A1 | R10: =UPPER(TRIM(Q10)) -> LON-A1 | S10: 46312
A11: PRD00010 | B11: EC-ACC-0010 | C11: =UPPER(TRIM(B11)) -> EC-ACC-0010 | D11: Urban Field Essential Screen Protector - Black | E11: =TRIM(D11) -> Urban Field Essential Screen Protector - Black | F11: Accessories | G11: =PROPER(TRIM(F11)) -> Accessories | H11: Urban Field | I11: {=PROPER(IF(TRIM(H11)<>"",TRIM(H11),IFERROR(INDEX('Brand Reference'!$A$2:$A$13,MATCH(TRUE,ISNUMBER(SEARCH('Brand Reference'!$A$2:$A$13,E11)),0)),"Unknown")))} -> Urban Field | J11: Bluegate Distribution | K11: =IF(J11="","Unknown",TRIM(PROPER(J11))) -> Bluegate Distribution | L11: 39.56 | M11: 77.19 | N11: =VALUE(SUBSTITUTE(M11," GBP","")) -> 77.19 | O11: 42 | P11: 15 | Q11: GLA-A2 | R11: =UPPER(TRIM(Q11)) -> GLA-A2 | S11: 45799
A12: PRD00011 | B12: EC-GAR-0011 | C12: =UPPER(TRIM(B12)) -> EC-GAR-0011 | D12: Oak & Ember Eco Garden Gloves - Rose | E12: =TRIM(D12) -> Oak & Ember Eco Garden Gloves - Rose | F12: Garden | G12: =PROPER(TRIM(F12)) -> Garden | H12: Oak & Ember | I12: {=PROPER(IF(TRIM(H12)<>"",TRIM(H12),IFERROR(INDEX('Brand Reference'!$A$2:$A$13,MATCH(TRUE,ISNUMBER(SEARCH('Brand Reference'!$A$2:$A$13,E12)),0)),"Unknown")))} -> Oak & Ember | J12: Harbour Stockists | K12: =IF(J12="","Unknown",TRIM(PROPER(J12))) -> Harbour Stockists | L12: 28.15 | M12: 56.06 | N12: =VALUE(SUBSTITUTE(M12," GBP","")) -> 56.06 | O12: 251 | P12: 12 | Q12: GLA-A2 | R12: =UPPER(TRIM(Q12)) -> GLA-A2
A13: PRD00012 | B13: EC-TRA-0012 | C13: =UPPER(TRIM(B13)) -> EC-TRA-0012 | D13: Kindred Travel Packing Cubes - Sage | E13: =TRIM(D13) -> Kindred Travel Packing Cubes - Sage | F13: Travel | G13: =PROPER(TRIM(F13)) -> Travel | H13: Kindred | I13: {=PROPER(IF(TRIM(H13)<>"",TRIM(H13),IFERROR(INDEX('Brand Reference'!$A$2:$A$13,MATCH(TRUE,ISNUMBER(SEARCH('Brand Reference'!$A$2:$A$13,E13)),0)),"Unknown")))} -> Kindred | J13: Crownline Imports | K13: =IF(J13="","Unknown",TRIM(PROPER(J13))) -> Crownline Imports | L13: 57.56 | M13: 136.91 | N13: =VALUE(SUBSTITUTE(M13," GBP","")) -> 136.91 | O13: 156 | P13: 30 | Q13: GLA-A2 | R13: =UPPER(TRIM(Q13)) -> GLA-A2 | S13: 46091
A14: PRD00013 | B14: EC-HOM-0013 | C14: =UPPER(TRIM(B14)) -> EC-HOM-0013 | D14: Northstar Compact LED Strip Lights | E14: =TRIM(D14) -> Northstar Compact LED Strip Lights | F14: Home & Office | G14: =PROPER(TRIM(F14)) -> Home & Office | H14: Northstar | I14: {=PROPER(IF(TRIM(H14)<>"",TRIM(H14),IFERROR(INDEX('Brand Reference'!$A$2:$A$13,MATCH(TRUE,ISNUMBER(SEARCH('Brand Reference'!$A$2:$A$13,E14)),0)),"Unknown")))} -> Northstar | J14: Ivory Peak Logistics | K14: =IF(J14="","Unknown",TRIM(PROPER(J14))) -> Ivory Peak Logistics | L14: 6.45 | M14: 11.17 | N14: =VALUE(SUBSTITUTE(M14," GBP","")) -> 11.17 | O14: 180 | P14: 5 | Q14: BHM-C3 | R14: =UPPER(TRIM(Q14)) -> BHM-C3 | S14: 45344
A15: PRD00014 | B15: ec-fit-0014 | C15: =UPPER(TRIM(B15)) -> EC-FIT-0014 | D15: Morrow Mini Yoga Mat | E15: =TRIM(D15) -> Morrow Mini Yoga Mat | F15: Fitness | G15: =PROPER(TRIM(F15)) -> Fitness | H15: Morrow | I15: {=PROPER(IF(TRIM(H15)<>"",TRIM(H15),IFERROR(INDEX('Brand Reference'!$A$2:$A$13,MATCH(TRUE,ISNUMBER(SEARCH('Brand Reference'!$A$2:$A$13,E15)),0)),"Unknown")))} -> Morrow | J15: Greenway Goods | K15: =IF(J15="","Unknown",TRIM(PROPER(J15))) -> Greenway Goods | L15: 40.83 | M15: 82.9 | N15: =VALUE(SUBSTITUTE(M15," GBP","")) -> 82.9 | O15: 87 | P15: 12 | Q15: GLA-A2 | R15: =UPPER(TRIM(Q15)) -> GLA-A2 | S15: 45715
A16: PRD00015 | B16: EC-BEA-0015 | C16: =UPPER(TRIM(B16)) -> EC-BEA-0015 | D16: Kite & Key Everyday Facial Cleanser | E16: =TRIM(D16) -> Kite & Key Everyday Facial Cleanser | F16: Beauty | G16: =PROPER(TRIM(F16)) -> Beauty | H16: KITE & KEY | I16: {=PROPER(IF(TRIM(H16)<>"",TRIM(H16),IFERROR(INDEX('Brand Reference'!$A$2:$A$13,MATCH(TRUE,ISNUMBER(SEARCH('Brand Reference'!$A$2:$A$13,E16)),0)),"Unknown")))} -> Kite & Key | J16: Harbour Stockists | K16: =IF(J16="","Unknown",TRIM(PROPER(J16))) -> Harbour Stockists | L16: 5.03 | M16: 10.37 | N16: =VALUE(SUBSTITUTE(M16," GBP","")) -> 10.37 | O16: 88 | P16: 5 | Q16: LDS-B1 | R16: =UPPER(TRIM(Q16)) -> LDS-B1 | S16: 45390
A17: PRD00016 | B17: EC-BEA-0016 | C17: =UPPER(TRIM(B17)) -> EC-BEA-0016 | D17: Kindred Eco Hand Cream - Black | E17: =TRIM(D17) -> Kindred Eco Hand Cream - Black | F17: Beauty | G17: =PROPER(TRIM(F17)) -> Beauty | H17: KINDRED | I17: {=PROPER(IF(TRIM(H17)<>"",TRIM(H17),IFERROR(INDEX('Brand Reference'!$A$2:$A$13,MATCH(TRUE,ISNUMBER(SEARCH('Brand Reference'!$A$2:$A$13,E17)),0)),"Unknown")))} -> Kindred | J17: Greenway Goods | K17: =IF(J17="","Unknown",TRIM(PROPER(J17))) -> Greenway Goods | L17: 46.08 | M17: 102.02 GBP | N17: =VALUE(SUBSTITUTE(M17," GBP","")) -> 102.02 | O17: 70 | P17: 12 | Q17: MAN-A1 | R17: =UPPER(TRIM(Q17)) -> MAN-A1 | S17: 45672
A18: PRD00017 | B18: EC-GAR-0017 | C18: =UPPER(TRIM(B18)) -> EC-GAR-0017 | D18: Harbour & Hill Compact Garden Gloves | E18: =TRIM(D18) -> Harbour & Hill Compact Garden Gloves | F18: Garden | G18: =PROPER(TRIM(F18)) -> Garden | H18: Harbour & Hill | I18: {=PROPER(IF(TRIM(H18)<>"",TRIM(H18),IFERROR(INDEX('Brand Reference'!$A$2:$A$13,MATCH(TRUE,ISNUMBER(SEARCH('Brand Reference'!$A$2:$A$13,E18)),0)),"Unknown")))} -> Harbour & Hill | J18: Harbour Stockists | K18: =IF(J18="","Unknown",TRIM(PROPER(J18))) -> Harbour Stockists | L18: 30.69 | M18: 50.33 GBP | N18: =VALUE(SUBSTITUTE(M18," GBP","")) -> 50.33 | O18: 254 | P18: 30 | Q18: LON-B2 | R18: =UPPER(TRIM(Q18)) -> LON-B2 | S18: 45881
A19: PRD00018 | B19: EC-PET-0018 | C19: =UPPER(TRIM(B19)) -> EC-PET-0018 | D19: Morrow Essential Cat Toy | E19: =TRIM(D19) -> Morrow Essential Cat Toy | F19: Pet supplies | G19: =PROPER(TRIM(F19)) -> Pet Supplies | H19: Morrow | I19: {=PROPER(IF(TRIM(H19)<>"",TRIM(H19),IFERROR(INDEX('Brand Reference'!$A$2:$A$13,MATCH(TRUE,ISNUMBER(SEARCH('Brand Reference'!$A$2:$A$13,E19)),0)),"Unknown")))} -> Morrow | J19: Aster Wholesale Ltd | K19: =IF(J19="","Unknown",TRIM(PROPER(J19))) -> Aster Wholesale Ltd | L19: 45.65 | M19: 75.38 | N19: =VALUE(SUBSTITUTE(M19," GBP","")) -> 75.38 | O19: 48 | P19: 15 | Q19: lon-a1 | R19: =UPPER(TRIM(Q19)) -> LON-A1 | S19: 45765
A20: PRD00019 | B20: EC-KIT-0019 | C20: =UPPER(TRIM(B20)) -> EC-KIT-0019 | D20: Harbour & Hill Travel Coffee Grinder | E20: =TRIM(D20) -> Harbour & Hill Travel Coffee Grinder | F20: kitchen | G20: =PROPER(TRIM(F20)) -> Kitchen | H20: Harbour & Hill | I20: {=PROPER(IF(TRIM(H20)<>"",TRIM(H20),IFERROR(INDEX('Brand Reference'!$A$2:$A$13,MATCH(TRUE,ISNUMBER(SEARCH('Brand Reference'!$A$2:$A$13,E20)),0)),"Unknown")))} -> Harbour & Hill | J20: Ivory Peak Logistics | K20: =IF(J20="","Unknown",TRIM(PROPER(J20))) -> Ivory Peak Logistics | L20: 31.34 | M20: 47.71 | N20: =VALUE(SUBSTITUTE(M20," GBP","")) -> 47.71 | O20: 110 | P20: 10 | Q20: GLA-A2 | R20: =UPPER(TRIM(Q20)) -> GLA-A2 | S20: 45866
A21: PRD00020 | B21: EC-HOM-0020 | C21: =UPPER(TRIM(B21)) -> EC-HOM-0020 | D21: Kite & Key Pro Water Bottle | E21: =TRIM(D21) -> Kite & Key Pro Water Bottle | F21: Home & Office | G21: =PROPER(TRIM(F21)) -> Home & Office | H21: Kite & Key | I21: {=PROPER(IF(TRIM(H21)<>"",TRIM(H21),IFERROR(INDEX('Brand Reference'!$A$2:$A$13,MATCH(TRUE,ISNUMBER(SEARCH('Brand Reference'!$A$2:$A$13,E21)),0)),"Unknown")))} -> Kite & Key | J21: Crownline Imports | K21: =IF(J21="","Unknown",TRIM(PROPER(J21))) -> Crownline Imports | L21: 48.21 | M21: 70.46 | N21: =VALUE(SUBSTITUTE(M21," GBP","")) -> 70.46 | O21: 135 | P21: 10 | Q21: LON-A1 | R21: =UPPER(TRIM(Q21)) -> LON-A1 | S21: 46185
A22: PRD00021 | B22: EC-ELE-0021 | C22: =UPPER(TRIM(B22)) -> EC-ELE-0021 | D22: PixelWorks Plus Laptop Stand | E22: =TRIM(D22) -> PixelWorks Plus Laptop Stand | F22: Electronics | G22: =PROPER(TRIM(F22)) -> Electronics | H22: PixelWorks | I22: {=PROPER(IF(TRIM(H22)<>"",TRIM(H22),IFERROR(INDEX('Brand Reference'!$A$2:$A$13,MATCH(TRUE,ISNUMBER(SEARCH('Brand Reference'!$A$2:$A$13,E22)),0)),"Unknown")))} -> Pixelworks | J22: Crownline Imports | K22: =IF(J22="","Unknown",TRIM(PROPER(J22))) -> Crownline Imports | L22: 11 | M22: 18.64 | N22: =VALUE(SUBSTITUTE(M22," GBP","")) -> 18.64 | O22: 32 | P22: 20 | Q22: MAN-A1 | R22: =UPPER(TRIM(Q22)) -> MAN-A1 | S22: 45936
A23: PRD00022 | B23: EC-ELE-0022 | C23: =UPPER(TRIM(B23)) -> EC-ELE-0022 | D23: Northstar Deluxe Mechanical Keyboard | E23: =TRIM(D23) -> Northstar Deluxe Mechanical Keyboard | F23: Electronics | G23: =PROPER(TRIM(F23)) -> Electronics | H23: Northstar | I23: {=PROPER(IF(TRIM(H23)<>"",TRIM(H23),IFERROR(INDEX('Brand Reference'!$A$2:$A$13,MATCH(TRUE,ISNUMBER(SEARCH('Brand Reference'!$A$2:$A$13,E23)),0)),"Unknown")))} -> Northstar | J23: Bluegate Distribution | K23: =IF(J23="","Unknown",TRIM(PROPER(J23))) -> Bluegate Distribution | L23: 3.48 | M23: 5.07 GBP | N23: =VALUE(SUBSTITUTE(M23," GBP","")) -> 5.07 | O23: 11 | P23: 20 | Q23: LDS-B1 | R23: =UPPER(TRIM(Q23)) -> LDS-B1 | S23: 45543
A24: PRD00023 | B24: EC-BOO-0023 | C24: =UPPER(TRIM(B24)) -> EC-BOO-0023 | D24: PixelWorks Mini Cookbook | E24: =TRIM(D24) -> PixelWorks Mini Cookbook | F24: Books | G24: =PROPER(TRIM(F24)) -> Books | H24: PixelWorks | I24: {=PROPER(IF(TRIM(H24)<>"",TRIM(H24),IFERROR(INDEX('Brand Reference'!$A$2:$A$13,MATCH(TRUE,ISNUMBER(SEARCH('Brand Reference'!$A$2:$A$13,E24)),0)),"Unknown")))} -> Pixelworks | J24: Juniper Merchants | K24: =IF(J24="","Unknown",TRIM(PROPER(J24))) -> Juniper Merchants | L24: 56.41 | M24: 114.32 | N24: =VALUE(SUBSTITUTE(M24," GBP","")) -> 114.32 | O24: 206 | P24: 25 | Q24: bhm-c3 | R24: =UPPER(TRIM(Q24)) -> BHM-C3 | S24: 45733
A25: PRD00024 | B25: EC-ELE-0024 | C25: =UPPER(TRIM(B25)) -> EC-ELE-0024 | D25: Nova Supply Mini Webcam | E25: =TRIM(D25) -> Nova Supply Mini Webcam | F25: Electronics | G25: =PROPER(TRIM(F25)) -> Electronics | H25: Nova Supply | I25: {=PROPER(IF(TRIM(H25)<>"",TRIM(H25),IFERROR(INDEX('Brand Reference'!$A$2:$A$13,MATCH(TRUE,ISNUMBER(SEARCH('Brand Reference'!$A$2:$A$13,E25)),0)),"Unknown")))} -> Nova Supply | J25: Aster Wholesale Ltd | K25: =IF(J25="","Unknown",TRIM(PROPER(J25))) -> Aster Wholesale Ltd | L25: 78.69 | M25: 139.91 | N25: =VALUE(SUBSTITUTE(M25," GBP","")) -> 139.91 | O25: 182 | P25: 5 | Q25: MAN-A1 | R25: =UPPER(TRIM(Q25)) -> MAN-A1 | S25: 46186
A26: PRD00025 | B26: EC-KIT-0025 | C26: =UPPER(TRIM(B26)) -> EC-KIT-0025 | D26: Oak & Ember Plus Coffee Grinder | E26: =TRIM(D26) -> Oak & Ember Plus Coffee Grinder | F26: kitchen | G26: =PROPER(TRIM(F26)) -> Kitchen | H26: Oak & Ember | I26: {=PROPER(IF(TRIM(H26)<>"",TRIM(H26),IFERROR(INDEX('Brand Reference'!$A$2:$A$13,MATCH(TRUE,ISNUMBER(SEARCH('Brand Reference'!$A$2:$A$13,E26)),0)),"Unknown")))} -> Oak & Ember | J26: Ivory Peak Logistics | K26: =IF(J26="","Unknown",TRIM(PROPER(J26))) -> Ivory Peak Logistics | L26: 36.7 | M26: 73.19 | N26: =VALUE(SUBSTITUTE(M26," GBP","")) -> 73.19 | O26: 10 | P26: 25 | Q26: LON-A1 | R26: =UPPER(TRIM(Q26)) -> LON-A1 | S26: 45696
A27: PRD00026 | B27: EC-ELE-0026 | C27: =UPPER(TRIM(B27)) -> EC-ELE-0026 | D27: Urban Field Studio Webcam - White | E27: =TRIM(D27) -> Urban Field Studio Webcam - White | F27: Electronics | G27: =PROPER(TRIM(F27)) -> Electronics | H27: urban field | I27: {=PROPER(IF(TRIM(H27)<>"",TRIM(H27),IFERROR(INDEX('Brand Reference'!$A$2:$A$13,MATCH(TRUE,ISNUMBER(SEARCH('Brand Reference'!$A$2:$A$13,E27)),0)),"Unknown")))} -> Urban Field | J27: Juniper Merchants | K27: =IF(J27="","Unknown",TRIM(PROPER(J27))) -> Juniper Merchants | L27: 12.61 | M27: 21.93 GBP | N27: =VALUE(SUBSTITUTE(M27," GBP","")) -> 21.93 | O27: 154 | P27: 5 | Q27: LON-B2 | R27: =UPPER(TRIM(Q27)) -> LON-B2 | S27: 46161
A28: PRD00027 | B28: EC-ACC-0027 | C28: =UPPER(TRIM(B28)) -> EC-ACC-0027 | D28: Harbour & Hill Deluxe Screen Protector | E28: =TRIM(D28) -> Harbour & Hill Deluxe Screen Protector | F28: Accessories | G28: =PROPER(TRIM(F28)) -> Accessories | H28: Harbour & Hill | I28: {=PROPER(IF(TRIM(H28)<>"",TRIM(H28),IFERROR(INDEX('Brand Reference'!$A$2:$A$13,MATCH(TRUE,ISNUMBER(SEARCH('Brand Reference'!$A$2:$A$13,E28)),0)),"Unknown")))} -> Harbour & Hill | J28: Everwell Supply | K28: =IF(J28="","Unknown",TRIM(PROPER(J28))) -> Everwell Supply | L28: 57.06 | M28: 125.67 | N28: =VALUE(SUBSTITUTE(M28," GBP","")) -> 125.67 | O28: 93 | P28: 5 | Q28: LON-B2 | R28: =UPPER(TRIM(Q28)) -> LON-B2 | S28: 46104
A29: PRD00028 | B29: EC-ELE-0028 | C29: =UPPER(TRIM(B29)) -> EC-ELE-0028 | D29: Northstar Pro USB-C Hub | E29: =TRIM(D29) -> Northstar Pro USB-C Hub | F29: electronics | G29: =PROPER(TRIM(F29)) -> Electronics | H29: Northstar | I29: {=PROPER(IF(TRIM(H29)<>"",TRIM(H29),IFERROR(INDEX('Brand Reference'!$A$2:$A$13,MATCH(TRUE,ISNUMBER(SEARCH('Brand Reference'!$A$2:$A$13,E29)),0)),"Unknown")))} -> Northstar | J29: Ivory Peak Logistics | K29: =IF(J29="","Unknown",TRIM(PROPER(J29))) -> Ivory Peak Logistics | L29: 24.04 | M29: 40.78 | N29: =VALUE(SUBSTITUTE(M29," GBP","")) -> 40.78 | O29: 45 | P29: 12 | Q29: MAN-A1 | R29: =UPPER(TRIM(Q29)) -> MAN-A1 | S29: 45369
A30: PRD00029 | B30: ec-pet-0029 | C30: =UPPER(TRIM(B30)) -> EC-PET-0029 | D30: Kindred Mini Cat Toy | E30: =TRIM(D30) -> Kindred Mini Cat Toy | F30: Pet supplies | G30: =PROPER(TRIM(F30)) -> Pet Supplies | H30: kindred | I30: {=PROPER(IF(TRIM(H30)<>"",TRIM(H30),IFERROR(INDEX('Brand Reference'!$A$2:$A$13,MATCH(TRUE,ISNUMBER(SEARCH('Brand Reference'!$A$2:$A$13,E30)),0)),"Unknown")))} -> Kindred | J30: Ivory Peak Logistics | K30: =IF(J30="","Unknown",TRIM(PROPER(J30))) -> Ivory Peak Logistics | L30: 3.14 | M30: 7.62 | N30: =VALUE(SUBSTITUTE(M30," GBP","")) -> 7.62 | O30: 240 | P30: 5 | Q30: LON-B2 | R30: =UPPER(TRIM(Q30)) -> LON-B2 | S30: 45746
A31: PRD00030 | B31: EC-ACC-0030 | C31: =UPPER(TRIM(B31)) -> EC-ACC-0030 | D31: Kindred Mini Phone Case | E31: =TRIM(D31) -> Kindred Mini Phone Case | F31: Accessories | G31: =PROPER(TRIM(F31)) -> Accessories | H31: KINDRED | I31: {=PROPER(IF(TRIM(H31)<>"",TRIM(H31),IFERROR(INDEX('Brand Reference'!$A$2:$A$13,MATCH(TRUE,ISNUMBER(SEARCH('Brand Reference'!$A$2:$A$13,E31)),0)),"Unknown")))} -> Kindred | J31: Harbour Stockists | K31: =IF(J31="","Unknown",TRIM(PROPER(J31))) -> Harbour Stockists | L31: 25.03 | M31: 57.5 | N31: =VALUE(SUBSTITUTE(M31," GBP","")) -> 57.5 | O31: 191 | P31: 25 | Q31: GLA-A2 | R31: =UPPER(TRIM(Q31)) -> GLA-A2 | S31: 46232
A32: PRD00031 | B32: EC-HOM-0031 | C32: =UPPER(TRIM(B32)) -> EC-HOM-0031 | D32: Oak & Ember Everyday Desk Organiser | E32: =TRIM(D32) -> Oak & Ember Everyday Desk Organiser | F32: Home & Office | G32: =PROPER(TRIM(F32)) -> Home & Office | H32: Oak & Ember | I32: {=PROPER(IF(TRIM(H32)<>"",TRIM(H32),IFERROR(INDEX('Brand Reference'!$A$2:$A$13,MATCH(TRUE,ISNUMBER(SEARCH('Brand Reference'!$A$2:$A$13,E32)),0)),"Unknown")))} -> Oak & Ember | J32: Crownline Imports | K32: =IF(J32="","Unknown",TRIM(PROPER(J32))) -> Crownline Imports | L32: 14.93 | M32: 34.83 | N32: =VALUE(SUBSTITUTE(M32," GBP","")) -> 34.83 | O32: 181 | P32: 30 | Q32: LON-A1 | R32: =UPPER(TRIM(Q32)) -> LON-A1 | S32: 45368
A33: PRD00032 | B33: EC-KIT-0032 | C33: =UPPER(TRIM(B33)) -> EC-KIT-0032 | D33: Cedar Lane Plus Food Storage Set - Sage | E33: =TRIM(D33) -> Cedar Lane Plus Food Storage Set - Sage | F33: Kitchen | G33: =PROPER(TRIM(F33)) -> Kitchen | H33: Cedar Lane | I33: {=PROPER(IF(TRIM(H33)<>"",TRIM(H33),IFERROR(INDEX('Brand Reference'!$A$2:$A$13,MATCH(TRUE,ISNUMBER(SEARCH('Brand Reference'!$A$2:$A$13,E33)),0)),"Unknown")))} -> Cedar Lane | J33: Juniper Merchants | K33: =IF(J33="","Unknown",TRIM(PROPER(J33))) -> Juniper Merchants | L33: 63.43 | M33: 155.32 GBP | N33: =VALUE(SUBSTITUTE(M33," GBP","")) -> 155.32 | O33: 9 | P33: 15 | Q33: LON-A1 | R33: =UPPER(TRIM(Q33)) -> LON-A1 | S33: 45920
A34: PRD00033 | B34: EC-HOM-0033 | C34: =UPPER(TRIM(B34)) -> EC-HOM-0033 | D34: Cedar Lane Travel LED Strip Lights | E34: =TRIM(D34) -> Cedar Lane Travel LED Strip Lights | F34: Home & Office | G34: =PROPER(TRIM(F34)) -> Home & Office | H34: Cedar Lane | I34: {=PROPER(IF(TRIM(H34)<>"",TRIM(H34),IFERROR(INDEX('Brand Reference'!$A$2:$A$13,MATCH(TRUE,ISNUMBER(SEARCH('Brand Reference'!$A$2:$A$13,E34)),0)),"Unknown")))} -> Cedar Lane | J34: Everwell Supply | K34: =IF(J34="","Unknown",TRIM(PROPER(J34))) -> Everwell Supply | L34: 10.89 | M34: 16.4 | N34: =VALUE(SUBSTITUTE(M34," GBP","")) -> 16.4 | O34: 199 | P34: 25 | Q34: lon-a1 | R34: =UPPER(TRIM(Q34)) -> LON-A1 | S34: 45827
A35: PRD00034 | B35: EC-HOM-0034 | C35: =UPPER(TRIM(B35)) -> EC-HOM-0034 | D35: Nova Supply Everyday Desk Organiser | E35: =TRIM(D35) -> Nova Supply Everyday Desk Organiser | F35: Home & Office | G35: =PROPER(TRIM(F35)) -> Home & Office | H35: Nova Supply | I35: {=PROPER(IF(TRIM(H35)<>"",TRIM(H35),IFERROR(INDEX('Brand Reference'!$A$2:$A$13,MATCH(TRUE,ISNUMBER(SEARCH('Brand Reference'!$A$2:$A$13,E35)),0)),"Unknown")))} -> Nova Supply | J35: Aster Wholesale Ltd | K35: =IF(J35="","Unknown",TRIM(PROPER(J35))) -> Aster Wholesale Ltd | L35: 26.65 | M35: 44.35 | N35: =VALUE(SUBSTITUTE(M35," GBP","")) -> 44.35 | O35: 68 | P35: 30 | Q35: GLA-A2 | R35: =UPPER(TRIM(Q35)) -> GLA-A2 | S35: 45678
A36: PRD00035 | B36: EC-BEA-0035 | C36: =UPPER(TRIM(B36)) -> EC-BEA-0035 | D36: Harbour & Hill Mini Hand Cream - Natural | E36: =TRIM(D36) -> Harbour & Hill Mini Hand Cream - Natural | F36: Beauty | G36: =PROPER(TRIM(F36)) -> Beauty | H36: Harbour & Hill | I36: {=PROPER(IF(TRIM(H36)<>"",TRIM(H36),IFERROR(INDEX('Brand Reference'!$A$2:$A$13,MATCH(TRUE,ISNUMBER(SEARCH('Brand Reference'!$A$2:$A$13,E36)),0)),"Unknown")))} -> Harbour & Hill | J36: Bluegate Distribution | K36: =IF(J36="","Unknown",TRIM(PROPER(J36))) -> Bluegate Distribution | L36: 44.94 | M36: 69.55 | N36: =VALUE(SUBSTITUTE(M36," GBP","")) -> 69.55 | O36: 74 | P36: 12 | Q36: GLA-A2 | R36: =UPPER(TRIM(Q36)) -> GLA-A2 | S36: 45350
A37: PRD00036 | B37: EC-ELE-0036 | C37: =UPPER(TRIM(B37)) -> EC-ELE-0036 | D37: PixelWorks Compact Wireless Mouse | E37: =TRIM(D37) -> PixelWorks Compact Wireless Mouse | F37: electronics | G37: =PROPER(TRIM(F37)) -> Electronics | H37: PixelWorks | I37: {=PROPER(IF(TRIM(H37)<>"",TRIM(H37),IFERROR(INDEX('Brand Reference'!$A$2:$A$13,MATCH(TRUE,ISNUMBER(SEARCH('Brand Reference'!$A$2:$A$13,E37)),0)),"Unknown")))} -> Pixelworks | J37: Foxbridge Partners | K37: =IF(J37="","Unknown",TRIM(PROPER(J37))) -> Foxbridge Partners | L37: 46.26 | M37: 92.96 | N37: =VALUE(SUBSTITUTE(M37," GBP","")) -> 92.96 | O37: 127 | P37: 12 | Q37: BHM-C3 | R37: =UPPER(TRIM(Q37)) -> BHM-C3 | S37: 45509
A38: PRD00037 | B38: EC-ELE-0037 | C38: =UPPER(TRIM(B38)) -> EC-ELE-0037 | D38: Harbour & Hill Pro Mechanical Keyboard | E38: =TRIM(D38) -> Harbour & Hill Pro Mechanical Keyboard | F38: Electronics | G38: =PROPER(TRIM(F38)) -> Electronics | H38: Harbour & Hill | I38: {=PROPER(IF(TRIM(H38)<>"",TRIM(H38),IFERROR(INDEX('Brand Reference'!$A$2:$A$13,MATCH(TRUE,ISNUMBER(SEARCH('Brand Reference'!$A$2:$A$13,E38)),0)),"Unknown")))} -> Harbour & Hill | J38: Foxbridge Partners | K38: =IF(J38="","Unknown",TRIM(PROPER(J38))) -> Foxbridge Partners | L38: 11.93 | M38: 22.33 | N38: =VALUE(SUBSTITUTE(M38," GBP","")) -> 22.33 | O38: 255 | P38: 10 | Q38: LDS-B1 | R38: =UPPER(TRIM(Q38)) -> LDS-B1 | S38: 45797
A39: PRD00038 | B39: EC-HOM-0038 | C39: =UPPER(TRIM(B39)) -> EC-HOM-0038 | D39: PixelWorks Compact Desk Organiser | E39: =TRIM(D39) -> PixelWorks Compact Desk Organiser | F39: Home & Office | G39: =PROPER(TRIM(F39)) -> Home & Office | H39: PixelWorks | I39: {=PROPER(IF(TRIM(H39)<>"",TRIM(H39),IFERROR(INDEX('Brand Reference'!$A$2:$A$13,MATCH(TRUE,ISNUMBER(SEARCH('Brand Reference'!$A$2:$A$13,E39)),0)),"Unknown")))} -> Pixelworks | J39: Crownline Imports | K39: =IF(J39="","Unknown",TRIM(PROPER(J39))) -> Crownline Imports | L39: 9.48 | M39: 17.96 | N39: =VALUE(SUBSTITUTE(M39," GBP","")) -> 17.96 | O39: 159 | P39: 20 | Q39: MAN-A1 | R39: =UPPER(TRIM(Q39)) -> MAN-A1 | S39: 45754
A40: PRD00039 | B40: EC-PET-0039 | C40: =UPPER(TRIM(B40)) -> EC-PET-0039 | D40: Cedar Lane Mini Dog Lead | E40: =TRIM(D40) -> Cedar Lane Mini Dog Lead | F40: Pet Supplies | G40: =PROPER(TRIM(F40)) -> Pet Supplies | H40: Cedar Lane | I40: {=PROPER(IF(TRIM(H40)<>"",TRIM(H40),IFERROR(INDEX('Brand Reference'!$A$2:$A$13,MATCH(TRUE,ISNUMBER(SEARCH('Brand Reference'!$A$2:$A$13,E40)),0)),"Unknown")))} -> Cedar Lane | J40: Dovetail Trading Co. | K40: =IF(J40="","Unknown",TRIM(PROPER(J40))) -> Dovetail Trading Co. | L40: 62.13 | M40: 142.46 | N40: =VALUE(SUBSTITUTE(M40," GBP","")) -> 142.46 | O40: 206 | P40: 25 | Q40: BHM-C3 | R40: =UPPER(TRIM(Q40)) -> BHM-C3 | S40: 45653
...

Sheet Original_dataset
A1: product_id | B1: sku | C1: product_name | D1: category | E1: brand | F1: supplier | G1: unit_cost_gbp | H1: selling_price_gbp | I1: stock_quantity | J1: reorder_level | K1: warehouse_location | L1: last_restocked
A2: PRD00001 | B2: EC-ELE-0001 | C2: PixelWorks Travel Webcam | D2: Electronics | E2: PixelWorks | F2: Dovetail Trading Co. | G2: 81.1 | H2: 188.36 | I2: 215 | J2: 40 | K2: LON-A1 | L2: 46195
A3: PRD00002 | B3: EC-ELE-0002 | C3: Everyday Co. Pro Phone Charger | D3: Electronics | E3: Everyday Co. | F3: Everwell Supply | G3: 69.66 | H3: 146.54 GBP | I3: 160 | J3: 15 | K3: MAN-A1 | L3: not recorded
A4: PRD00003 | B4: ec-hom-0003 | C4: Kindred Travel LED Strip Lights | D4: Home & Office | E4: Kindred | F4: Juniper Merchants | G4: 9.62 | H4: 18.68 | I4: 147 | J4: 40 | K4: MAN-A1 | L4: 45580
A5: PRD00004 | B5: EC-KIT-0004 | C5: PixelWorks Essential Food Storage Set - Charcoal | D5: Kitchen | E5: PIXELWORKS | F5: Greenway Goods | G5: 75.97 | H5: 148.89 | I5: 59 | J5: 30 | K5: GLA-A2 | L5: 46297
A6: PRD00005 | B6: EC-ACC-0005 | C6: Kite & Key Essential Screen Protector | D6: Accessories | E6: Kite & Key | F6: Juniper Merchants | G6: 4.3 | H6: 6.87 | I6: 66 | J6: 5 | K6: BHM-C3 | L6: 45502
A7: PRD00006 | B7: EC-HOM-0006 | C7: Morrow Everyday Desk Lamp | D7: Home & Office | E7: MORROW | F7: Ivory Peak Logistics | G7: 40.02 | H7: 74.69 | I7: 128 | J7: 30 | K7: LDS-B1 | L7: 45922
A8: PRD00007 | B8: EC-BEA-0007 | C8: Harbour & Hill Deluxe Hand Cream | D8: Beauty | E8: HARBOUR & HILL | F8: Dovetail Trading Co. | G8: 24.48 | H8: 33.94 | J8: 40 | K8: MAN-A1 | L8: 46029
A9: PRD00008 | B9: EC-BEA-0008 | C9: Morrow Travel Shampoo | D9: beauty | E9: Morrow | F9: Bluegate Distribution | G9: 48.39 | H9: 113.62 | I9: 148 | J9: 25 | K9: BHM-C3 | L9: 46229
A10: PRD00009 | B10: EC-PET-0009 | C10: Oak & Ember Essential Dog Lead | D10: Pet Supplies | E10: Oak & Ember | G10: 71.95 | H10: 135.05 | I10: 32 | J10: 20 | K10: LON-A1 | L10: 46312
A11: PRD00010 | B11: EC-ACC-0010 | C11: Urban Field Essential Screen Protector - Black | D11: Accessories | E11: Urban Field | F11: Bluegate Distribution | G11: 39.56 | H11: 77.19 | I11: 42 | J11: 15 | K11: GLA-A2 | L11: 45799
A12: PRD00011 | B12: EC-GAR-0011 | C12: Oak & Ember Eco Garden Gloves - Rose | D12: Garden | E12: Oak & Ember | F12: Harbour Stockists | G12: 28.15 | H12: 56.06 | I12: 251 | J12: 12 | K12: GLA-A2 | L12: not recorded
A13: PRD00012 | B13: EC-TRA-0012 | C13: Kindred Travel Packing Cubes - Sage | D13: Travel | E13: Kindred | F13: Crownline Imports | G13: 57.56 | H13: 136.91 | I13: 156 | J13: 30 | K13: GLA-A2 | L13: 46091
A14: PRD00013 | B14: EC-HOM-0013 | C14: Northstar Compact LED Strip Lights | D14: Home & Office | E14: Northstar | F14: Ivory Peak Logistics | G14: 6.45 | H14: 11.17 | I14: 180 | J14: 5 | K14: BHM-C3 | L14: 45344
A15: PRD00014 | B15: ec-fit-0014 | C15: Morrow Mini Yoga Mat | D15: Fitness | E15: Morrow | F15: Greenway Goods | G15: 40.83 | H15: 82.9 | I15: 87 | J15: 12 | K15: GLA-A2 | L15: 45715
A16: PRD00015 | B16: EC-BEA-0015 | C16: Kite & Key Everyday Facial Cleanser | D16: Beauty | E16: KITE & KEY | F16: Harbour Stockists | G16: 5.03 | H16: 10.37 | I16: 88 | J16: 5 | K16: LDS-B1 | L16: 45390
A17: PRD00016 | B17: EC-BEA-0016 | C17: Kindred Eco Hand Cream - Black | D17: Beauty | E17: KINDRED | F17: Greenway Goods | G17: 46.08 | H17: 102.02 GBP | I17: 70 | J17: 12 | K17: MAN-A1 | L17: 45672
A18: PRD00017 | B18: EC-GAR-0017 | C18: Harbour & Hill Compact Garden Gloves | D18: Garden | E18: Harbour & Hill | F18: Harbour Stockists | G18: 30.69 | H18: 50.33 GBP | I18: 254 | J18: 30 | K18: LON-B2 | L18: 45881
A19: PRD00018 | B19: EC-PET-0018 | C19: Morrow Essential Cat Toy | D19: Pet supplies | E19: Morrow | F19: Aster Wholesale Ltd | G19: 45.65 | H19: 75.38 | I19: 48 | J19: 15 | K19: lon-a1 | L19: 45765
A20: PRD00019 | B20: EC-KIT-0019 | C20: Harbour & Hill Travel Coffee Grinder | D20: kitchen | E20: Harbour & Hill | F20: Ivory Peak Logistics | G20: 31.34 | H20: 47.71 | I20: 110 | J20: 10 | K20: GLA-A2 | L20: 45866
A21: PRD00020 | B21: EC-HOM-0020 | C21: Kite & Key Pro Water Bottle | D21: Home & Office | E21: Kite & Key | F21: Crownline Imports | G21: 48.21 | H21: 70.46 | I21: 135 | J21: 10 | K21: LON-A1 | L21: 46185
A22: PRD00021 | B22: EC-ELE-0021 | C22: PixelWorks Plus Laptop Stand | D22: Electronics | E22: PIXELWORKS | F22: Crownline Imports | G22: 11 | H22: 18.64 | I22: 32 | J22: 20 | K22: MAN-A1 | L22: 45936
A23: PRD00022 | B23: EC-ELE-0022 | C23: Northstar Deluxe Mechanical Keyboard | D23: Electronics | E23: Northstar | F23: Bluegate Distribution | G23: 3.48 | H23: 5.07 GBP | I23: 11 | J23: 20 | K23: LDS-B1 | L23: 45543
A24: PRD00023 | B24: EC-BOO-0023 | C24: PixelWorks Mini Cookbook | D24: Books | E24: PixelWorks | F24: Juniper Merchants | G24: 56.41 | H24: 114.32 | I24: 206 | J24: 25 | K24: bhm-c3 | L24: 45733
A25: PRD00024 | B25: EC-ELE-0024 | C25: Nova Supply Mini Webcam | D25: Electronics | E25: Nova Supply | F25: Aster Wholesale Ltd | G25: 78.69 | H25: 139.91 | I25: 182 | J25: 5 | K25: MAN-A1 | L25: 46186
A26: PRD00025 | B26: EC-KIT-0025 | C26: Oak & Ember Plus Coffee Grinder | D26: kitchen | E26: Oak & Ember | F26: Ivory Peak Logistics | G26: 36.7 | H26: 73.19 | I26: 10 | J26: 25 | K26: LON-A1 | L26: 45696
A27: PRD00026 | B27: EC-ELE-0026 | C27: Urban Field Studio Webcam - White | D27: Electronics | E27: urban field | F27: Juniper Merchants | G27: 12.61 | H27: 21.93 GBP | I27: 154 | J27: 5 | K27: LON-B2 | L27: 46161
A28: PRD00027 | B28: EC-ACC-0027 | C28: Harbour & Hill Deluxe Screen Protector | D28: Accessories | E28: Harbour & Hill | F28: Everwell Supply | G28: 57.06 | H28: 125.67 | I28: 93 | J28: 5 | K28: LON-B2 | L28: 46104
A29: PRD00028 | B29: EC-ELE-0028 | C29: Northstar Pro USB-C Hub | D29: electronics | E29: Northstar | F29: Ivory Peak Logistics | G29: 24.04 | H29: 40.78 | I29: 45 | J29: 12 | K29: MAN-A1 | L29: 45369
A30: PRD00029 | B30: ec-pet-0029 | C30: Kindred Mini Cat Toy | D30: Pet supplies | E30: kindred | F30: Ivory Peak Logistics | G30: 3.14 | H30: 7.62 | I30: 240 | J30: 5 | K30: LON-B2 | L30: 45746
A31: PRD00030 | B31: EC-ACC-0030 | C31: Kindred Mini Phone Case | D31: Accessories | E31: KINDRED | F31: Harbour Stockists | G31: 25.03 | H31: 57.5 | I31: 191 | J31: 25 | K31: GLA-A2 | L31: 46232
A32: PRD00031 | B32: EC-HOM-0031 | C32: Oak & Ember Everyday Desk Organiser | D32: Home & Office | E32: Oak & Ember | F32: Crownline Imports | G32: 14.93 | H32: 34.83 | I32: 181 | J32: 30 | K32: LON-A1 | L32: 45368
A33: PRD00032 | B33: EC-KIT-0032 | C33: Cedar Lane Plus Food Storage Set - Sage | D33: Kitchen | E33: Cedar Lane | F33: Juniper Merchants | G33: 63.43 | H33: 155.32 GBP | I33: 9 | J33: 15 | K33: LON-A1 | L33: 45920
A34: PRD00033 | B34: EC-HOM-0033 | C34: Cedar Lane Travel LED Strip Lights | D34: Home and office | E34: Cedar Lane | F34: Everwell Supply | G34: 10.89 | H34: 16.4 | I34: 199 | J34: 25 | K34: lon-a1 | L34: 45827
A35: PRD00034 | B35: EC-HOM-0034 | C35: Nova Supply Everyday Desk Organiser | D35: Home & Office | E35: Nova Supply | F35: Aster Wholesale Ltd | G35: 26.65 | H35: 44.35 | I35: 68 | J35: 30 | K35: GLA-A2 | L35: 45678
A36: PRD00035 | B36: EC-BEA-0035 | C36: Harbour & Hill Mini Hand Cream - Natural | D36: Beauty | E36: Harbour & Hill | F36: Bluegate Distribution | G36: 44.94 | H36: 69.55 | I36: 74 | J36: 12 | K36: GLA-A2 | L36: 45350
A37: PRD00036 | B37: EC-ELE-0036 | C37: PixelWorks Compact Wireless Mouse | D37: electronics | E37: PIXELWORKS | F37: Foxbridge Partners | G37: 46.26 | H37: 92.96 | I37: 127 | J37: 12 | K37: BHM-C3 | L37: 45509
A38: PRD00037 | B38: EC-ELE-0037 | C38: Harbour & Hill Pro Mechanical Keyboard | D38: Electronics | E38: Harbour & Hill | F38: Foxbridge Partners | G38: 11.93 | H38: 22.33 | I38: 255 | J38: 10 | K38: LDS-B1 | L38: 45797
A39: PRD00038 | B39: EC-HOM-0038 | C39: PixelWorks Compact Desk Organiser | D39: Home & Office | E39: PixelWorks | F39: Crownline Imports | G39: 9.48 | H39: 17.96 | I39: 159 | J39: 20 | K39: MAN-A1 | L39: 45754
A40: PRD00039 | B40: EC-PET-0039 | C40: Cedar Lane Mini Dog Lead | D40: Pet Supplies | E40: Cedar Lane | F40: Dovetail Trading Co. | G40: 62.13 | H40: 142.46 | I40: 206 | J40: 25 | K40: BHM-C3 | L40: 45653
...

Sheet Brand Reference
A1: Brand Reference
A2: Oak & Ember
A3: Everyday Co.
A4: Harbour & Hill
A5: PixelWorks
A6: Morrow
A7: Kite & Key
A8: Urban Field
A9: Northstar
A10: Nova Supply
A11: Cedar Lane
A12: Kindred
A13: Brightline
